Workbook
Name Additional_Instance: 'Static Reference Tables'!$H$11:$H$13
Name administrator_vsphere_local_password: 'Value Reference Tables'!$L$13
Name asn_instance: 'Value Reference Tables - MR'!$AH$18
Name asn_mgmt_az1: 'Value Reference Tables - MR'!$AH$19
Name asn_mgmt_az2: 'Value Reference Tables - MR'!$AH$20
Name asn_start: 'Value Reference Tables - MR'!$AH$17
Name asn_wld_az1: 'Value Reference Tables - MR'!$AH$21
Name asn_wld_az2: 'Value Reference Tables - MR'!$AH$22
Name aws_regions: 'Static Reference Tables'!$B$576:$B$603
Name ca_administrator_password: 'Value Reference Tables'!$L$30
Name ca_administrator_username: 'Value Reference Tables'!$L$8
Name ca_algorithm: 'Value Reference Tables'!$O$39
Name ca_country: 'Value Reference Tables'!$O$38
Name ca_email_address: 'Value Reference Tables'!$O$41
Name ca_key_size: 'Value Reference Tables'!$O$40
Name ca_locality: 'Value Reference Tables'!$O$42
Name ca_organization: 'Value Reference Tables'!$O$43
Name ca_organization_unit: 'Value Reference Tables'!$O$44
Name ca_state: 'Value Reference Tables'!$O$45
Name ca_template_name: 'Value Reference Tables'!$O$37
Name calculated_mgmt_host_count: 'Management Domain Sizing'!$R$8
Name certificate_authority_fqdn: 'Value Reference Tables'!$L$57
Name certificate_authority_model: 'Value Reference Tables'!$O$9
Name certificate_authority_name: 'Value Reference Tables'!$L$58
Name change_control_new: 'Change Control'!$B$2:$B$100
Name change_control_old: 'Change Control'!$C$2:$C$100
Name child_dns_zone: 'Value Reference Tables'!$L$66
Name cluster_az1_host_fqdns: 'Value Reference Tables'!$I$75:$I$90
Name cluster_az1_host_mgmt_ips: 'Value Reference Tables'!$I$57:$I$72
Name cluster_az1_host_overlay_cidr: 'Value Reference Tables'!$I$162
Name cluster_az1_host_overlay_gateway_ip: 'Value Reference Tables'!$I$165
Name cluster_az1_host_overlay_network_pool_description: 'Value Reference Tables'!$I$161
Name cluster_az1_host_overlay_network_pool_name: 'Value Reference Tables'!$I$160
Name cluster_az1_host_overlay_network_profile_name: 'Value Reference Tables'!$I$110
Name cluster_az1_host_overlay_new_pool_chosen: 'Deploy Cluster'!$D$247
Name cluster_az1_host_overlay_pool_end_ip: 'Value Reference Tables'!$I$164
Name cluster_az1_host_overlay_pool_start_ip: 'Value Reference Tables'!$I$163
Name cluster_az1_host_overlay_transport_zone: 'Value Reference Tables'!$I$156
Name cluster_az1_host_overlay_uplink_profile_name: 'Value Reference Tables'!$I$170
Name cluster_az1_host_overlay_vlan: 'Value Reference Tables'!$I$157
Name cluster_az1_host1_fqdn: 'Value Reference Tables'!$I$75
Name cluster_az1_host1_mgmt_ip: 'Value Reference Tables'!$I$57
Name cluster_az1_host10_fqdn: 'Value Reference Tables'!$I$84
Name cluster_az1_host10_mgmt_ip: 'Value Reference Tables'!$I$66
Name cluster_az1_host11_fqdn: 'Value Reference Tables'!$I$85
Name cluster_az1_host11_mgmt_ip: 'Value Reference Tables'!$I$67
Name cluster_az1_host12_fqdn: 'Value Reference Tables'!$I$86
Name cluster_az1_host12_mgmt_ip: 'Value Reference Tables'!$I$68
Name cluster_az1_host13_fqdn: 'Value Reference Tables'!$I$87
Name cluster_az1_host13_mgmt_ip: 'Value Reference Tables'!$I$69
Name cluster_az1_host14_fqdn: 'Value Reference Tables'!$I$88
Name cluster_az1_host14_mgmt_ip: 'Value Reference Tables'!$I$70
Name cluster_az1_host15_fqdn: 'Value Reference Tables'!$I$89
Name cluster_az1_host15_mgmt_ip: 'Value Reference Tables'!$I$71
Name cluster_az1_host16_fqdn: 'Value Reference Tables'!$I$90
Name cluster_az1_host16_mgmt_ip: 'Value Reference Tables'!$I$72
Name cluster_az1_host2_fqdn: 'Value Reference Tables'!$I$76
Name cluster_az1_host2_mgmt_ip: 'Value Reference Tables'!$I$58
Name cluster_az1_host3_fqdn: 'Value Reference Tables'!$I$77
Name cluster_az1_host3_mgmt_ip: 'Value Reference Tables'!$I$59

Sheet Prerequisite Checklist
B2: Prerequisite Checklist
B3: The following pre-requisites need to be completed before proceeding with deployments
B6: Hardware (Management Domain)
B7: Server Component | C7: Minimum Requirements | D7: Notes
B8: Server Type | C8: Two Supported Servers - Simple Deployment ( NFS / FC) Three Supported Servers - Simple Deployment ( vSAN) Four Supported Servers - High Availability Deployment | D8: Refer to the VMware Compatibility Guide at https://compatibilityguide.broadcom.com/ for supported configurations. Note that VMware Cloud Foundation supports three node vSAN clusters in Workload Domains. VMware recommends a minimum of four nodes for production.
B9: CPU | C9: Supported Configurations | D9: None
B10: Memory | C10: Supported Configurations | D10: Rainpole example suggests - 1TB per host based on 4 hosts with ability to tolerate failure of a single host. Use Management Domain Sizing for sizing based on your chosen options.
B11: Storage (Boot) | C11: Supported configurations | D11: SD-Cards are considered legacy and not recommended.
B12: Storage VSAN-OSA (Cache) | C12: Supported Configurations | D12: Rainpole example suggests - 1.2TB of Raw Capacity for the Caching Tier (All-Flash) per host. - Two disk groups, 600GB cache per disk group. Ensure no existing partitions exist on disks intended for use See Designing and Sizing a vSAN Cluster from the VMware vSAN documentation for guidelines about cache sizing. Use Management Domain Sizing for sizing based on your chosen options.
B13: Storage vSAN-OSA (Capacity) | C13: Supported Configurations | D13: Rainpole example suggests - 12.5TB of Raw Capacity for the Capacity Tier (All-Flash) per host. - Two disk groups, 6.25TB per disk group Ensure no existing partitions exist on disks intended for use Use Management Domain Sizing for sizing based on your chosen options.
B14: Storage vSAN-ESA | C14: Supported Configurations | D14: Rainpole example suggests - 12.5TB of Raw Capacity for the Capacity Tier (All-Flash) per host. - 4 x 3.2TB NVME SSD Drives per node. Ensure no existing partitions exist on disks intended for use Use Management Domain Sizing for sizing based on your chosen options.
B15: Storage NFS | C15: Supported Configurations | D15: Use Management Domain Sizing for sizing based on your chosen options.
B16: Storage FC | C16: Supported Configurations | D16: Use Management Domain Sizing for sizing based on your chosen options.
B17: NICs per server | C17: - One 10 GbE NICs - One 1 GbE BMC NIC | D17: Single NIC is supported with API Only 25GbE NICs are recommended for vSAN ESA
B19: Hardware (Workload Domain)
B20: Server Component | C20: Minimum Requirements | D20: Notes
B21: Type | C21: Three Supported Servers | D21: Refer to the VMware Compatibility Guide at https://www.vmware.com/resources/compatibility/search.php for supported configurations. Note that VMware Cloud Foundation supports three node vSAN clusters in Workload Domains. VMware recommends a minimum of four nodes for production. Ensure no existing partitions exist on disks intended for use
B22: CPU | C22: Supported configurations
B23: Memory | C23: Supported configurations
B24: Storage (Boot) | C24: Supported configurations
B25: Storage vSAN-OSA (Cache) | C25: Supported configurations
B26: Storage vSAN-OSA(Capacity) | C26: Supported configurations
B27: Storage vSAN-ESA | C27: Supported configurations
B28: Storage NFS | C28: Supported configurations
B29: Storage FC | C29: Supported configurations
B30: NICs per server | C30: - One 10 GbE NICs - One 1 GbE BMC NIC | D30: Single NIC is supported with API Only VI Workload Domain: Supports a maximum of 64 x pNICs per host 25GbE NICs are recommended for vSAN ESA
B32: Network Requirements
B33: Configuration | C33: Feature | D33: Notes
B34: Physical Network | C34: Jumbo frames | D34: Required for the following traffic types: - vSAN - vSphere vMotion - ESX Host Overlay - NSX Edge Overlay - NFS
C35: BGP adjacency and BGP autonomous system (AS) numbers | D35: Required for Dynamic routing in the SDDC
C36: Teaming Configurations | D36: Use teaming options within vSphere Distributed Switch to provide load-balancing and failover.
C37: Multi-path routing | D37: Verfiy that Equal-cost multi-path routing (ECMP) is supported on interfaces between NSX Edge uplinks and Top-of Rack Switchs (ToRs)
C38: Stretched Network Requirements (Multiple Availability Zone Environments Only) | D38: Verify that routing is in place between ESXI Management IP subnets of Availability Zone 1 (AZ1) and Availability Zone 2 (AZ2). Verify that the following networks from AZ1 are are stretched across the two availability zones. - VM Management network - Uplink01 (If NSX Centralized Connectivity is enabled for Management Domain, or Centralized Connectivity is enabled for Workload Domain) - Uplink02 (If NSX Centralized Connectivity is enabled for Management Domain, or Centralized Connectivity is enabled for Workload Domain) - Edge Overlay (If NSX Centralized Connectivity is enabled for Management Domain, or Centralized Connectivity is enabled for Workload Domain)
B40: VMware Software, Scripts, and Tools
B41: Software | C41: Download Location | D41: Download | E41: Notes
B42: VMware Cloud Foundation Installer | C42: support.broadcom.com | D42: VCF-SDDC-Manager-Appliance-9.1.x.0.xxxxxxxx
B43: vSAN Witness Appliance | C43: support.broadcom.com | D43: VMware-VirtualSAN-Witness-x.x.x-xxxxxxxx.ova | E43: You use this when deploying a witness appliance to a different fault domain when adding secondary availability zones.
B45: Third Party Software
B46: Software | C46: Vendor | D46: Product / Version | E46: Notes
B47: Virtual Infrastructure | C47: Any Supported | D47: Operating system for VMware vSphere® deployment. | E47: A host machine in the data center that has access to the ESX management and VM Management Network.
...

Sheet VCF & VVF Planning
B2: VMware Cloud Foundation and VMware vSphere Foundation Planning
B3: Use this page to select your options for a VMware Cloud Foundation Deployment | M3: =pnp_version_number -> v1.9.1.102
B6: VMware Values
B7: At VMware we value inclusion. To foster this principle within our customer, partner, and internal community, we are replacing some of the terminology in our content. We have updated this document to remove instances of non-inclusive language.
J9: Version
J10: VMware Cloud Foundation
J11: =IF(vcf_version_chosen="No Version Selected","Select Version",vcf_version_chosen) -> 9.1.1.0
J14: Deployment Type
J15: Select Option | K15: Feature | L15: Final Result | M15: Information
J16: 9.1.1.0 | K16: =CONCATENATE(mgmt_domain_deployment_type_chosen," Deployment Version") -> VMware Cloud Foundation Deployment Version | L16: =IF(vcf_version_chosen="No Version Selected","Excluded","Included") -> Included | M16: =IF(vcf_version_result="Excluded",CONCATENATE("Cause: ",mgmt_domain_deployment_type_chosen, " Deployment Version is not selected"),CONCATENATE(mgmt_domain_deployment_type_chosen," Version ",vcf_version," selected")) -> VMware Cloud Foundation Version 9.1.1.0 selected
J17: VMware Cloud Foundation | K17: Deployment Specification | L17: =IF(vcf_version_chosen="No Version Selected","Excluded","Included") -> Included | M17: =IF(vcf_version_result="Excluded",CONCATENATE("Cause: ",mgmt_domain_deployment_type_chosen, " Deployment Version is not selected"),IF(mgmt_domain_deployment_type_chosen="VMware Cloud Foundation","VMware Cloud Foundation Private Cloud will be deployed","VMware vSphere Foundation will be deployed")) -> VMware Cloud Foundation Private Cloud will be deployed
J18: First Instance | K18: Instance to perform operation on | L18: =IF(vcf_version_chosen="No Version Selected","Excluded",IF(mgmt_domain_deployment_type_chosen="VMware vSphere Foundation","Excluded",IF(mgmt_domain_chosen="Deploy a new VCF fleet","Included","Included"))) -> Included | M18: =IF(vcf_version_result="Excluded",CONCATENATE("Cause: ",mgmt_domain_deployment_type_chosen, " Deployment Version is not selected"),IF(mgmt_domain_deployment_type_chosen="VMware vSphere Foundation","Option not required for deployment specification type",IF(mgmt_domain_chosen="First Instance","Operation will be performed on the First VCF Instance","Operation will be performed on an additional VCF Instance"))) -> Operation will be performed on the First VCF Instance
J19: Deploy a new VCF fleet | K19: Operation to be performed | L19: =IF(vcf_version_chosen="No Version Selected","Excluded", IF(AND(mgmt_domain_deployment_type_chosen="VMware vSphere Foundation",vcf_granular_option_chosen="Create Workload Domain"),"Excluded", IF(AND(mgmt_domain_deployment_type_chosen="VMware vSphere Foundation",vcf_granular_option_chosen="Create Cluster"),"Excluded", IF(AND(mgmt_domain_deployment_type_chosen="VMware Cloud Foundation",vcf_granular_option_chosen="VMware vSphere Foundation Deployment"),"Excluded", IF(vcf_granular_option_chosen="None Chosen","Excluded","Included"))))) -> Included | M19: =IF(vcf_version_result="Excluded",CONCATENATE("Cause: ",mgmt_domain_deployment_type_chosen," Deployment Version is not selected"), IF(AND(mgmt_domain_deployment_type_chosen="VMware vSphere Foundation",vcf_granular_option_chosen="Create Workload Domain"),"Option not supported for deployment specification type", IF(AND(mgmt_domain_deployment_type_chosen="VMware vSphere Foundation",vcf_granular_option_chosen="Create Cluster"),"Option not supported for deployment specification type", IF(AND(mgmt_domain_deployment_type_chosen="VMware Cloud Foundation",vcf_granular_option_chosen="VMware vSphere Foundation Deployment"),"Option not supported for deployment specification type", IF(vcf_granular_option_chosen="None Chosen","No Deployment Type Chosen",IF(vcf_granular_option_chosen="Deploy a new VCF fleet","VMware Cloud Foundation Installer will deploy a new VCF fleet", IF(vcf_granular_option_chosen="Deploy a VCF Instance in an existing VCF fleet","VMware Cloud Foundation Installer will deploy a new VCF Instance in an existing VCF fleet", IF(vcf_granular_option_chosen="Create Cluster","A cluster will be added to an existing Workload Domain", IF(vcf_granular_option_chosen="Create Workload Domain","A Workload Domain will be added to an exsiting VCF Instance", IF(vcf_granular_option_chosen="VMware vSphere Foundation Deployment","Deploy a new VMware vSphere Foundation Cluster", IF(vcf_granular_option_chosen="Deploy deferred components","Deploy the management components that you deffered during the inital deployment",""))))))))))) -> VMware Cloud Foundation Installer will deploy a new VCF fleet

Sheet Management Domain Sizing
B2: VMware Cloud Foundation Management Domain Sizing Inputs
B6: Management Domain Assumptions | G6: Management Domain Virtual Machine Requirement Summary | O6: Host Requirement Summary | U6: Notes
B7: Component | E7: Value | G7: Component | J7: Nodes | K7: vCPU | L7: RAM (GB) | M7: Disk (GB) | O7: Management Hosts | R7: Number of Hosts | U7: General Guidance • This sizing sheet is a standalone calculation. Inputs from other tabs within the workbook do not affect the final calculation. • Deployment Model and Size sets the predefined values as determined by VCF Installer. • Configure the Assumptions and Host parameters according to your preference. • The over-subscription ratio of 2:1 are designed to ensure a performant management domain for most deployments. Higher Ratios are supported. Regardless of the ratios you choose, you should monitor the platform continuously and add hardware if consistent performance bottlenecks are observed • Appliance sizes are listed per appliance. Totals are calculated in the requirements summary table • Select the principle storage as VCF 9.x Supports vSAN and Non-vSAN Storage in the Management Domain Customer Workload • Add additonal vCPU, RAM or Disk requirements that may be required to accurately size the Management Domain. vSphere and NSX Sizing • As each workload domain requires additional vSphere and, optionally, NSX components to be deployed, this tab allows you to correctly calculate the requirements for your management domain by selecting the intended number and profile of workload domains you plan to deploy. • The management domain is mandatory and cannot be deselected. Its NSX Manager instance is required and can be shared with future workload domains. • A maximum of four NSX Local Manager instances may be federated by a single NSX Global Manager instance. This includes inter-region and intra-region NSX Local Manager instances. Factor in this maximum when deciding whether to include Global Manager resources for a new workload domain. VCF Operations and Automation Sizing • If VCF Operations already exist, then sizing input is not required for VCF Operations. Similar for VCF Automation. • Cloud Proxy selection is automatic, if you are deploying VCF Operations or have an Exisiting VCF Operations. VCF services runtime • Components such as Software depot , LCM, Identity broker, SALT are enabled by default when deploying VCF service runtime on the first VCF Instance. • Components Realtime Data, Software depot and Identity broker are configured within the VCFMS instance. No additional appliances are deployed. • Real-time Metric, Log management, are enabled as part of day 2 deployment and are deployed within the VCFMS instance. • Log management size should not be larger and Instance Profile. The VCFMS Cluster will scale to accomodate the Log Managment Deployment. • Software depot and Identity broker are deployed, sized by default in the First VCF Instance. Optional Software depots and Identity broker deployments can be sized for additional VCF Instances. vCPU and RAM requirements for these compontent are allocated from the exisitng VCFMS cluster. Security Service Platform: • License Hub for vDefend and Avi is required if deploying Avi Load Balancers or Security Service Platform. A single License Hub is required per VCF Fleet. • SSPI = Security Services Platform Installer; SSP = Security Services Platform; A single SSP installer can manage up to 5 SSP instances. • The SSP form factor selection is based on the respective management or workload domain NSX Manager appliance size. A medium form factor is required to activate Security Intelligence. For a larger configuration and inventory scale, you must use the large or extra-large form factor. • To activate all vDefend Advanced Threat Prevention capabilities, including Malware Prevention Service, Network Traffic Analysis, NDR Sensor, and Network Detection and Response, you need a large SSP form factor with at least 8 worker nodes.
B8: Host and Operations Reserve (%) | E8: 30 | G8: SDDC Manager | J8: 1 | K8: =sizing_sddc_manager_cpu -> 4 | L8: =sizing_sddc_manager_ram -> 16 | M8: =sizing_sddc_manager_disk -> 914 | O8: Hosts count based on User Specification | R8: =IF(OR(H40="Mandatory - HA Cluster",sizing_vcf_deployment_model_chosen="Deploy HA"),MAX(4,(ROUNDUP(((SUM(K8:K29,K30)/sizing_cpu_oversubscription)/sizing_mgmt_cluster_host_core_count),0)),((ROUNDUP((SUM(L8:L29,L30)/sizing_mgmt_cluster_host_ram_count),0))+1)), IF(OR(sizing_storage_type="vSAN-ESA",sizing_storage_type="vSAN-OSA"),MAX(3,(ROUNDUP(((SUM(K8:K29,K30)/sizing_cpu_oversubscription)/sizing_mgmt_cluster_host_core_count),0)),((ROUNDUP((SUM(L8:L29,L30/sizing_ram_oversubscription)/sizing_mgmt_cluster_host_ram_count),0))+1)),MAX(2,(ROUNDUP(((SUM(K8:K30)/sizing_cpu_oversubscription)/sizing_mgmt_cluster_host_core_count),0)),((ROUNDUP((SUM(L8:L29,L30/sizing_ram_oversubscription)/sizing_mgmt_cluster_host_ram_count),0))+1)))) -> 4
B9: Storage Estimated Growth (%) | E9: 10 | G9: Management Domain vCenter | J9: 1 | K9: =IF(sizing_m01_included="Included",VLOOKUP(D40,table_vcenter_appliance_cpu,2,FALSE),0) -> 4 | L9: =IF(sizing_m01_included="Included",VLOOKUP(D40,table_vcenter_appliance_ram,2,FALSE),0) -> 21 | M9: =IF(sizing_m01_included="Included",VLOOKUP(CONCATENATE(D40,F40),table_vcenter_disk_gb,2,FALSE),0) -> 2084 | O9: CPU usage Per Host (based on N-1 hosts) | R9: =CONCATENATE(ROUNDUP(SUM(K8:K30)/(calculated_mgmt_host_count-1)/sizing_cpu_oversubscription,0)," CPUs") -> 23 CPUs
G10: Management Domain NSX Managers (Local / Global) | J10: =SUM(IF(sizing_m01_nsxt_model="Mandatory - Single Node",1,3),IF(sizing_m01_nsxt_gm_appliance_size<>"Excluded",3,0)) -> 3 | K10: =SUM(PRODUCT(VLOOKUP(sizing_m01_nsxt_appliance_size,table_nsxt_manager_cpu,2,FALSE),IF(sizing_m01_nsxt_model="Mandatory - HA Cluster",3,1)),(PRODUCT(IF(sizing_m01_nsxt_gm_appliance_size<>"Excluded",VLOOKUP(sizing_m01_nsxt_gm_appliance_size,table_nsxt_manager_cpu,2,FALSE),0),3))) -> 18 | L10: =SUM(PRODUCT(VLOOKUP(sizing_m01_nsxt_appliance_size,table_nsxt_manager_ram,2,FALSE),IF(sizing_m01_nsxt_model="Mandatory - HA Cluster",3,1)),(PRODUCT(IF(sizing_m01_nsxt_gm_appliance_size<>"Excluded",VLOOKUP(sizing_m01_nsxt_gm_appliance_size,table_nsxt_manager_ram,2,FALSE),0),3))) -> 72 | M10: =SUM(PRODUCT(VLOOKUP(sizing_m01_nsxt_appliance_size,table_nsxt_manager_disk_gb,2,FALSE),IF(sizing_m01_nsxt_model="Mandatory - HA Cluster",3,1)),(PRODUCT(IF(sizing_m01_nsxt_gm_appliance_size<>"Excluded",VLOOKUP(sizing_m01_nsxt_gm_appliance_size,table_nsxt_manager_disk_gb,2,FALSE),0),3))) -> 900 | O10: RAM usage Per Host (based on N-1 hosts) | R10: =CONCATENATE(ROUNDUP(SUM(L8:L30)/(calculated_mgmt_host_count-1)/sizing_ram_oversubscription,0)," GB RAM") -> 63 GB RAM
B11: Management Domain Host Parameters | G11: Management Domain NSX Edges | J11: =IF(AND(sizing_m01_nsxt_edge_size<>"Excluded",sizing_m01_nsxt_edge_size<>"VNA Small",sizing_m01_nsxt_edge_size<>"VNA Medium",sizing_m01_nsxt_edge_size<>"VNA Large",sizing_m01_nsxt_edge_size<>"VNA XLarge"),2,0) -> 0 | K11: =PRODUCT(IF(AND(sizing_m01_nsxt_edge_size<>"Excluded",sizing_m01_nsxt_edge_size<>"VNA Small",sizing_m01_nsxt_edge_size<>"VNA Medium",sizing_m01_nsxt_edge_size<>"VNA Large",sizing_m01_nsxt_edge_size<>"VNA XLarge",sizing_m01_included="Included"),VLOOKUP(sizing_m01_nsxt_edge_size,table_nsxt_edge_cpu,2,FALSE),0),J11) -> 0 | L11: =PRODUCT(IF(AND(sizing_m01_nsxt_edge_size<>"Excluded",sizing_m01_nsxt_edge_size<>"VNA Small",sizing_m01_nsxt_edge_size<>"VNA Medium",sizing_m01_nsxt_edge_size<>"VNA Large",sizing_m01_nsxt_edge_size<>"VNA XLarge",sizing_m01_included="Included"),VLOOKUP(sizing_m01_nsxt_edge_size,table_nsxt_edge_ram,2,FALSE),0),2) -> 0 | M11: =PRODUCT(IF(AND(sizing_m01_nsxt_edge_size<>"Excluded",sizing_m01_nsxt_edge_size<>"VNA Small",sizing_m01_nsxt_edge_size<>"VNA Medium",sizing_m01_nsxt_edge_size<>"VNA Large",sizing_m01_nsxt_edge_size<>"VNA XLarge",sizing_m01_included="Included"),VLOOKUP(sizing_m01_nsxt_edge_size,table_nsxt_edge_disk_gb,2,FALSE),0),J11) -> 0
B12: Attribute | E12: Value | G12: Management Domain Virtual Network Appliances | J12: =IF(AND(sizing_m01_nsxt_edge_size<>"Excluded",sizing_m01_nsxt_edge_size<>"NSX Edge Small",sizing_m01_nsxt_edge_size<>"NSX Edge Medium",sizing_m01_nsxt_edge_size<>"NSX Edge Large",sizing_m01_nsxt_edge_size<>"NSX Edge XLarge"),2,0) -> 0 | K12: =PRODUCT(IF(AND(sizing_m01_nsxt_edge_size<>"Excluded",sizing_m01_nsxt_edge_size<>"NSX Edge Small",sizing_m01_nsxt_edge_size<>"NSX Edge Medium",sizing_m01_nsxt_edge_size<>"NSX Edge Large",sizing_m01_nsxt_edge_size<>"NSX Edge XLarge",sizing_m01_included="Included"),VLOOKUP(sizing_m01_nsxt_edge_size,table_nsxt_edge_cpu,2,FALSE),0),J12) -> 0 | L12: =PRODUCT(IF(AND(sizing_m01_nsxt_edge_size<>"Excluded",sizing_m01_nsxt_edge_size<>"NSX Edge Small",sizing_m01_nsxt_edge_size<>"NSX Edge Medium",sizing_m01_nsxt_edge_size<>"NSX Edge Large",sizing_m01_nsxt_edge_size<>"NSX Edge XLarge",sizing_m01_included="Included"),VLOOKUP(sizing_m01_nsxt_edge_size,table_nsxt_edge_ram,2,FALSE),0),J12) -> 0 | M12: =PRODUCT(IF(AND(sizing_m01_nsxt_edge_size<>"Excluded",sizing_m01_nsxt_edge_size<>"NSX Edge Small",sizing_m01_nsxt_edge_size<>"NSX Edge Medium",sizing_m01_nsxt_edge_size<>"NSX Edge Large",sizing_m01_nsxt_edge_size<>"NSX Edge XLarge",sizing_m01_included="Included"),VLOOKUP(sizing_m01_nsxt_edge_size,table_nsxt_edge_disk_gb,2,FALSE),0),J12) -> 0 | O12: vSAN Storage Requirements if used as Primary Storage
B13: CPU Cores | E13: 128 | G13: Management Domain Supervisor | J13: =IF(sizing_m01_supervisor_mode="Single Node",1,IF(sizing_m01_supervisor_mode="High Availability",3,0)) -> 0 | K13: =PRODUCT(IF(sizing_m01_supervisor_mode<>"Excluded",VLOOKUP(sizing_m01_supervisor_size,table_supervisor_cpu,2,FALSE),0),J13) -> 0 | L13: =PRODUCT(IF(sizing_m01_supervisor_mode<>"Excluded",VLOOKUP(sizing_m01_supervisor_size,table_supervisor_ram,2,FALSE),0),J13) -> 0 | M13: =PRODUCT(IF(sizing_m01_supervisor_mode<>"Excluded",VLOOKUP(sizing_m01_supervisor_size,table_supervisor_disk,2,FALSE),0),J13) -> 0 | O13: Storage Type | R13: vSAN-ESA
B14: RAM Count (GB) | E14: 1024 | G14: Management Domain AVI Load Balancer | J14: =IF(sizing_mgmt_avi_lb_appliance_size="Excluded",0,3) -> 0 | K14: =IF(sizing_mgmt_avi_lb_appliance_size="Excluded",0,PRODUCT(J14,IF(AND(sizing_m01_included="Included",sizing_mgmt_avi_lb_appliance_size<>"Excluded"),VLOOKUP(sizing_mgmt_avi_lb_appliance_size,table_avi_lb_cpu,2,FALSE),0))) -> 0 | L14: =IF(sizing_mgmt_avi_lb_appliance_size="Excluded",0,PRODUCT(J14,IF(AND(sizing_m01_included="Included",sizing_mgmt_avi_lb_appliance_size<>"Excluded"),VLOOKUP(sizing_mgmt_avi_lb_appliance_size,table_avi_lb_ram,2,FALSE),0))) -> 0 | M14: =IF(sizing_mgmt_avi_lb_appliance_size="Excluded",0,PRODUCT(J14,IF(AND(sizing_m01_included="Included",sizing_mgmt_avi_lb_appliance_size<>"Excluded"),VLOOKUP(sizing_mgmt_avi_lb_appliance_size,table_avi_lb_disk,2,FALSE),0))) -> 0 | O14: Component | R14: GB
B15: CPU Oversubscription (X:1) | E15: 1 | G15: Management Domain Security Services Platform | J15: =IF(sizing_m01_ssp_chosen<>"Excluded", SUM(VLOOKUP(sizing_m01_nsxt_appliance_size, table_ssp_workers, 2, FALSE), VLOOKUP(sizing_m01_nsxt_appliance_size, table_ssp_controller, 2, FALSE),VLOOKUP(sizing_m01_nsxt_appliance_size, table_ssp_sspi, 2, FALSE)), 0) -> 0 | K15: =IF(sizing_m01_ssp_chosen<>"Excluded",VLOOKUP(sizing_m01_nsxt_appliance_size,table_ssp_cpu,2,FALSE),0) -> 0 | L15: =IF(sizing_m01_ssp_chosen<>"Excluded",VLOOKUP(sizing_m01_nsxt_appliance_size,table_ssp_ram,2,FALSE),0) -> 0 | M15: =IF(sizing_m01_ssp_chosen<>"Excluded",VLOOKUP(sizing_m01_nsxt_appliance_size,table_ssp_disk,2,FALSE),0) -> 0 | O15: Virtual Machine Capacity Requirements | R15: =(SUM(M8:M30)) -> 6998
B16: Memory Oversubscription (X:1) | E16: 1 | G16: Security Services Platform Installer | J16: {=_xlfn.LET(_xlpm.c, _xlfn.VSTACK(W40, X44:X78), _xlpm.s, _xlfn.VSTACK(I40, I44:I78), _xlpm.cnts, _xlfn.SCAN(0, _xlpm.c, _xlfn.LAMBDA(_xlpm.a,_xlpm.v, _xlpm.a + (_xlpm.v = "Include"))), SUM(_xlfn.MAP(_xlpm.c, _xlpm.s, _xlpm.cnts, _xlfn.LAMBDA(_xlpm.chosen,_xlpm.size,_xlpm.cnt, IF(AND(_xlpm.chosen = "Include", MOD(_xlpm.cnt, 5) = 1), VLOOKUP(_xlpm.size, table_ssp_sspi, 2, FALSE), 0)))))} -> 0 | K16: {=_xlfn.LET(_xlpm.c, _xlfn.VSTACK(W40, X44:X78), _xlpm.s, _xlfn.VSTACK(I40, I44:I78), _xlpm.cnts, _xlfn.SCAN(0, _xlpm.c, _xlfn.LAMBDA(_xlpm.a,_xlpm.v, _xlpm.a + (_xlpm.v = "Include"))), SUM(_xlfn.MAP(_xlpm.c, _xlpm.s, _xlpm.cnts, _xlfn.LAMBDA(_xlpm.chosen,_xlpm.size,_xlpm.cnt, IF(AND(_xlpm.chosen = "Include", MOD(_xlpm.cnt, 5) = 1), VLOOKUP(_xlpm.size, table_ssp_sspi_cpu, 2, FALSE), 0)))))} -> 0 | L16: {=_xlfn.LET(_xlpm.c, _xlfn.VSTACK(W40, X44:X78), _xlpm.s, _xlfn.VSTACK(I40, I44:I78), _xlpm.cnts, _xlfn.SCAN(0, _xlpm.c, _xlfn.LAMBDA(_xlpm.a,_xlpm.v, _xlpm.a + (_xlpm.v = "Include"))), SUM(_xlfn.MAP(_xlpm.c, _xlpm.s, _xlpm.cnts, _xlfn.LAMBDA(_xlpm.chosen,_xlpm.size,_xlpm.cnt, IF(AND(_xlpm.chosen = "Include", MOD(_xlpm.cnt, 5) = 1), VLOOKUP(_xlpm.size, table_ssp_sspi_ram, 2, FALSE), 0)))))} -> 0 | M16: {=_xlfn.LET(_xlpm.c, _xlfn.VSTACK(W40, X44:X78), _xlpm.s, _xlfn.VSTACK(I40, I44:I78), _xlpm.cnts, _xlfn.SCAN(0, _xlpm.c, _xlfn.LAMBDA(_xlpm.a,_xlpm.v, _xlpm.a + (_xlpm.v = "Include"))), SUM(_xlfn.MAP(_xlpm.c, _xlpm.s, _xlpm.cnts, _xlfn.LAMBDA(_xlpm.chosen,_xlpm.size,_xlpm.cnt, IF(AND(_xlpm.chosen = "Include", MOD(_xlpm.cnt, 5) = 1), VLOOKUP(_xlpm.size, table_ssp_sspi_disk, 2, FALSE), 0)))))} -> 0 | O16: Swap File Requirements | R16: =CONCATENATE(SUM(L8:L30)) -> 187
G17: vDefend and AVI Licensing Hub | J17: =IF(sizing_vdefend_licensing_hub_chosen="Include",1,0) -> 0 | K17: =IF(sizing_vdefend_licensing_hub_chosen="Include",sizing_table_ssp_lic_cpu,0) -> 0 | L17: =IF(sizing_vdefend_licensing_hub_chosen="Include",sizing_table_ssp_lic_ram,0) -> 0 | M17: =IF(sizing_vdefend_licensing_hub_chosen="Include",sizing_table_ssp_lic_disk,0) -> 0 | O17: Interim Total (VM Capacity + Swap File) | R17: =R15+R16 -> 7185
B18: VCF Instance Profile | G18: Workload Domain vCenter | J18: =COUNTIF(C44:C78,"Included") -> 0 | K18: =(SUM(IF(sizing_w01_chosen="Included",VLOOKUP(sizing_w01_vcenter_appliance_size,table_vcenter_appliance_cpu,2,FALSE)), IF(sizing_w02_chosen="Included",VLOOKUP(sizing_w02_vcenter_appliance_size,table_vcenter_appliance_cpu,2,FALSE)), IF(sizing_w03_chosen="Included",VLOOKUP(sizing_w03_vcenter_appliance_size,table_vcenter_appliance_cpu,2,FALSE)), IF(sizing_w04_chosen="Included",VLOOKUP(sizing_w04_vcenter_appliance_size,table_vcenter_appliance_cpu,2,FALSE)), IF(sizing_w05_chosen="Included",VLOOKUP(sizing_w05_vcenter_appliance_size,table_vcenter_appliance_cpu,2,FALSE)), IF(sizing_w06_chosen="Included",VLOOKUP(sizing_w06_vcenter_appliance_size,table_vcenter_appliance_cpu,2,FALSE)), IF(sizing_w07_chosen="Included",VLOOKUP(sizing_w07_vcenter_appliance_size,table_vcenter_appliance_cpu,2,FALSE)), IF(sizing_w08_chosen="Included",VLOOKUP(sizing_w08_vcenter_appliance_size,table_vcenter_appliance_cpu,2,FALSE)), IF(sizing_w09_chosen="Included",VLOOKUP(sizing_w09_vcenter_appliance_size,table_vcenter_appliance_cpu,2,FALSE)), IF(sizing_w10_chosen="Included",VLOOKUP(sizing_w10_vcenter_appliance_size,table_vcenter_appliance_cpu,2,FALSE)), IF(sizing_w11_chosen="Included",VLOOKUP(sizing_w11_vcenter_appliance_size,table_vcenter_appliance_cpu,2,FALSE)), IF(sizing_w12_chosen="Included",VLOOKUP(sizing_w12_vcenter_appliance_size,table_vcenter_appliance_cpu,2,FALSE)), IF(sizing_w13_chosen="Included",VLOOKUP(sizing_w13_vcenter_appliance_size,table_vcenter_appliance_cpu,2,FALSE)), IF(sizing_w14_chosen="Included",VLOOKUP(sizing_w14_vcenter_appliance_size,table_vcenter_appliance_cpu,2,FALSE)), IF(sizing_w15_chosen="Included",VLOOKUP(sizing_w15_vcenter_appliance_size,table_vcenter_appliance_cpu,2,FALSE)), IF(sizing_w16_chosen="Included",VLOOKUP(sizing_w16_vcenter_appliance_size,table_vcenter_appliance_cpu,2,FALSE)), IF(sizing_w17_chosen="Included",VLOOKUP(sizing_w17_vcenter_appliance_size,table_vcenter_appliance_cpu,2,FALSE)), IF(sizing_w18_chosen="Included",VLOOKUP(sizing_w18_vcenter_appliance_size,table_vcenter_appliance_cpu,2,FALSE)), IF(sizing_w19_chosen="Included",VLOOKUP(sizing_w19_vcenter_appliance_size,table_vcenter_appliance_cpu,2,FALSE)), IF(sizing_w20_chosen="Included",VLOOKUP(sizing_w20_vcenter_appliance_size,table_vcenter_appliance_cpu,2,FALSE)), IF(sizing_w21_chosen="Included",VLOOKUP(sizing_w21_vcenter_appliance_size,table_vcenter_appliance_cpu,2,FALSE)), IF(sizing_w22_chosen="Included",VLOOKUP(sizing_w22_vcenter_appliance_size,table_vcenter_appliance_cpu,2,FALSE)), IF(sizing_w23_chosen="Included",VLOOKUP(sizing_w23_vcenter_appliance_size,table_vcenter_appliance_cpu,2,FALSE)), IF(sizing_w24_chosen="Included",VLOOKUP(sizing_w24_vcenter_appliance_size,table_vcenter_appliance_cpu,2,FALSE)), IF(sizing_w25_chosen="Included",VLOOKUP(sizing_w25_vcenter_appliance_size,table_vcenter_appliance_cpu,2,FALSE)), IF(sizing_w26_chosen="Included",VLOOKUP(sizing_w26_vcenter_appliance_size,table_vcenter_appliance_cpu,2,FALSE)), IF(sizing_w27_chosen="Included",VLOOKUP(sizing_w27_vcenter_appliance_size,table_vcenter_appliance_cpu,2,FALSE)), IF(sizing_w28_chosen="Included",VLOOKUP(sizing_w28_vcenter_appliance_size,table_vcenter_appliance_cpu,2,FALSE)), IF(sizing_w29_chosen="Included",VLOOKUP(sizing_w29_vcenter_appliance_size,table_vcenter_appliance_cpu,2,FALSE)), IF(sizing_w30_chosen="Included",VLOOKUP(sizing_w30_vcenter_appliance_size,table_vcenter_appliance_cpu,2,FALSE)), IF(sizing_w31_chosen="Included",VLOOKUP(sizing_w31_vcenter_appliance_size,table_vcenter_appliance_cpu,2,FALSE)), IF(sizing_w32_chosen="Included",VLOOKUP(sizing_w32_vcenter_appliance_size,table_vcenter_appliance_cpu,2,FALSE)), IF(sizing_w33_chosen="Included",VLOOKUP(sizing_w33_vcenter_appliance_size,table_vcenter_appliance_cpu,2,FALSE)), IF(sizing_w34_chosen="Included",VLOOKUP(sizing_w34_vcenter_appliance_size,table_vcenter_appliance_cpu,2,FALSE)), IF(sizing_w35_chosen="Included",VLOOKUP(sizing_w35_vcenter_appliance_size,table_vcenter_appliance_cpu,2,FALSE)), )) -> 0 | L18: =SUM(IF(sizing_w01_chosen="Included",VLOOKUP(sizing_w01_vcenter_appliance_size,table_vcenter_appliance_ram,2,FALSE)), IF(sizing_w02_chosen="Included",VLOOKUP(sizing_w02_vcenter_appliance_size,table_vcenter_appliance_ram,2,FALSE)), IF(sizing_w03_chosen="Included",VLOOKUP(sizing_w03_vcenter_appliance_size,table_vcenter_appliance_ram,2,FALSE)), IF(sizing_w04_chosen="Included",VLOOKUP(sizing_w04_vcenter_appliance_size,table_vcenter_appliance_ram,2,FALSE)), IF(sizing_w05_chosen="Included",VLOOKUP(sizing_w05_vcenter_appliance_size,table_vcenter_appliance_ram,2,FALSE)), IF(sizing_w06_chosen="Included",VLOOKUP(sizing_w06_vcenter_appliance_size,table_vcenter_appliance_ram,2,FALSE)), IF(sizing_w07_chosen="Included",VLOOKUP(sizing_w07_vcenter_appliance_size,table_vcenter_appliance_ram,2,FALSE)), IF(sizing_w08_chosen="Included",VLOOKUP(sizing_w08_vcenter_appliance_size,table_vcenter_appliance_ram,2,FALSE)), IF(sizing_w09_chosen="Included",VLOOKUP(sizing_w09_vcenter_appliance_size,table_vcenter_appliance_ram,2,FALSE)), IF(sizing_w10_chosen="Included",VLOOKUP(sizing_w10_vcenter_appliance_size,table_vcenter_appliance_ram,2,FALSE)), IF(sizing_w11_chosen="Included",VLOOKUP(sizing_w11_vcenter_appliance_size,table_vcenter_appliance_ram,2,FALSE)), IF(sizing_w12_chosen="Included",VLOOKUP(sizing_w12_vcenter_appliance_size,table_vcenter_appliance_ram,2,FALSE)), IF(sizing_w13_chosen="Included",VLOOKUP(sizing_w13_vcenter_appliance_size,table_vcenter_appliance_ram,2,FALSE)), IF(sizing_w14_chosen="Included",VLOOKUP(sizing_w14_vcenter_appliance_size,table_vcenter_appliance_ram,2,FALSE)), IF(sizing_w15_chosen="Included",VLOOKUP(sizing_w15_vcenter_appliance_size,table_vcenter_appliance_ram,2,FALSE)), IF(sizing_w16_chosen="Included",VLOOKUP(sizing_w16_vcenter_appliance_size,table_vcenter_appliance_ram,2,FALSE)), IF(sizing_w17_chosen="Included",VLOOKUP(sizing_w17_vcenter_appliance_size,table_vcenter_appliance_ram,2,FALSE)), IF(sizing_w18_chosen="Included",VLOOKUP(sizing_w18_vcenter_appliance_size,table_vcenter_appliance_ram,2,FALSE)), IF(sizing_w19_chosen="Included",VLOOKUP(sizing_w19_vcenter_appliance_size,table_vcenter_appliance_ram,2,FALSE)), IF(sizing_w20_chosen="Included",VLOOKUP(sizing_w20_vcenter_appliance_size,table_vcenter_appliance_ram,2,FALSE)), IF(sizing_w21_chosen="Included",VLOOKUP(sizing_w21_vcenter_appliance_size,table_vcenter_appliance_ram,2,FALSE)), IF(sizing_w22_chosen="Included",VLOOKUP(sizing_w22_vcenter_appliance_size,table_vcenter_appliance_ram,2,FALSE)), IF(sizing_w23_chosen="Included",VLOOKUP(sizing_w23_vcenter_appliance_size,table_vcenter_appliance_ram,2,FALSE)), IF(sizing_w24_chosen="Included",VLOOKUP(sizing_w24_vcenter_appliance_size,table_vcenter_appliance_ram,2,FALSE)), IF(sizing_w25_chosen="Included",VLOOKUP(sizing_w25_vcenter_appliance_size,table_vcenter_appliance_ram,2,FALSE)), IF(sizing_w26_chosen="Included",VLOOKUP(sizing_w26_vcenter_appliance_size,table_vcenter_appliance_ram,2,FALSE)), IF(sizing_w27_chosen="Included",VLOOKUP(sizing_w27_vcenter_appliance_size,table_vcenter_appliance_ram,2,FALSE)), IF(sizing_w28_chosen="Included",VLOOKUP(sizing_w28_vcenter_appliance_size,table_vcenter_appliance_ram,2,FALSE)), IF(sizing_w29_chosen="Included",VLOOKUP(sizing_w29_vcenter_appliance_size,table_vcenter_appliance_ram,2,FALSE)), IF(sizing_w30_chosen="Included",VLOOKUP(sizing_w30_vcenter_appliance_size,table_vcenter_appliance_ram,2,FALSE)), IF(sizing_w31_chosen="Included",VLOOKUP(sizing_w31_vcenter_appliance_size,table_vcenter_appliance_ram,2,FALSE)), IF(sizing_w32_chosen="Included",VLOOKUP(sizing_w32_vcenter_appliance_size,table_vcenter_appliance_ram,2,FALSE)), IF(sizing_w33_chosen="Included",VLOOKUP(sizing_w33_vcenter_appliance_size,table_vcenter_appliance_ram,2,FALSE)), IF(sizing_w34_chosen="Included",VLOOKUP(sizing_w34_vcenter_appliance_size,table_vcenter_appliance_ram,2,FALSE)), IF(sizing_w35_chosen="Included",VLOOKUP(sizing_w35_vcenter_appliance_size,table_vcenter_appliance_ram,2,FALSE)), ) -> 0 | M18: =SUM((IF(sizing_w01_chosen="Included",VLOOKUP(CONCATENATE(sizing_w01_vcenter_appliance_size,sizing_w01_vcenter_storage_size),table_vcenter_disk_gb,2,FALSE),0)), IF(sizing_w02_chosen="Included",VLOOKUP(CONCATENATE(sizing_w02_vcenter_appliance_size,sizing_w02_vcenter_storage_size),table_vcenter_disk_gb,2,FALSE),0), IF(sizing_w03_chosen="Included",VLOOKUP(CONCATENATE(sizing_w03_vcenter_appliance_size,sizing_w03_vcenter_storage_size),table_vcenter_disk_gb,2,FALSE),0), IF(sizing_w04_chosen="Included",VLOOKUP(CONCATENATE(sizing_w04_vcenter_appliance_size,sizing_w04_vcenter_storage_size),table_vcenter_disk_gb,2,FALSE),0), IF(sizing_w05_chosen="Included",VLOOKUP(CONCATENATE(sizing_w05_vcenter_appliance_size,sizing_w05_vcenter_storage_size),table_vcenter_disk_gb,2,FALSE),0), IF(sizing_w06_chosen="Included",VLOOKUP(CONCATENATE(sizing_w06_vcenter_appliance_size,sizing_w06_vcenter_storage_size),table_vcenter_disk_gb,2,FALSE),0), IF(sizing_w07_chosen="Included",VLOOKUP(CONCATENATE(sizing_w07_vcenter_appliance_size,sizing_w07_vcenter_storage_size),table_vcenter_disk_gb,2,FALSE),0), IF(sizing_w08_chosen="Included",VLOOKUP(CONCATENATE(sizing_w08_vcenter_appliance_size,sizing_w08_vcenter_storage_size),table_vcenter_disk_gb,2,FALSE),0), IF(sizing_w09_chosen="Included",VLOOKUP(CONCATENATE(sizing_w09_vcenter_appliance_size,sizing_w09_vcenter_storage_size),table_vcenter_disk_gb,2,FALSE),0), IF(sizing_w10_chosen="Included",VLOOKUP(CONCATENATE(sizing_w10_vcenter_appliance_size,sizing_w10_vcenter_storage_size),table_vcenter_disk_gb,2,FALSE),0), IF(sizing_w11_chosen="Included",VLOOKUP(CONCATENATE(sizing_w11_vcenter_appliance_size,sizing_w11_vcenter_storage_size),table_vcenter_disk_gb,2,FALSE),0), IF(sizing_w12_chosen="Included",VLOOKUP(CONCATENATE(sizing_w12_vcenter_appliance_size,sizing_w12_vcenter_storage_size),table_vcenter_disk_gb,2,FALSE),0), IF(sizing_w13_chosen="Included",VLOOKUP(CONCATENATE(sizing_w13_vcenter_appliance_size,sizing_w13_vcenter_storage_size),table_vcenter_disk_gb,2,FALSE),0), IF(sizing_w14_chosen="Included",VLOOKUP(CONCATENATE(sizing_w14_vcenter_appliance_size,sizing_w14_vcenter_storage_size),table_vcenter_disk_gb,2,FALSE),0), IF(sizing_w15_chosen="Included",VLOOKUP(CONCATENATE(sizing_w15_vcenter_appliance_size,sizing_w15_vcenter_storage_size),table_vcenter_disk_gb,2,FALSE),0), IF(sizing_w16_chosen="Included",VLOOKUP(CONCATENATE(sizing_w16_vcenter_appliance_size,sizing_w16_vcenter_storage_size),table_vcenter_disk_gb,2,FALSE),0), IF(sizing_w17_chosen="Included",VLOOKUP(CONCATENATE(sizing_w17_vcenter_appliance_size,sizing_w17_vcenter_storage_size),table_vcenter_disk_gb,2,FALSE),0), IF(sizing_w18_chosen="Included",VLOOKUP(CONCATENATE(sizing_w18_vcenter_appliance_size,sizing_w18_vcenter_storage_size),table_vcenter_disk_gb,2,FALSE),0), IF(sizing_w19_chosen="Included",VLOOKUP(CONCATENATE(sizing_w19_vcenter_appliance_size,sizing_w19_vcenter_storage_size),table_vcenter_disk_gb,2,FALSE),0), IF(sizing_w20_chosen="Included",VLOOKUP(CONCATENATE(sizing_w20_vcenter_appliance_size,sizing_w20_vcenter_storage_size),table_vcenter_disk_gb,2,FALSE),0), IF(sizing_w21_chosen="Included",VLOOKUP(CONCATENATE(sizing_w21_vcenter_appliance_size,sizing_w21_vcenter_storage_size),table_vcenter_disk_gb,2,FALSE),0), IF(sizing_w22_chosen="Included",VLOOKUP(CONCATENATE(sizing_w22_vcenter_appliance_size,sizing_w22_vcenter_storage_size),table_vcenter_disk_gb,2,FALSE),0), IF(sizing_w23_chosen="Included",VLOOKUP(CONCATENATE(sizing_w23_vcenter_appliance_size,sizing_w23_vcenter_storage_size),table_vcenter_disk_gb,2,FALSE),0), IF(sizing_w24_chosen="Included",VLOOKUP(CONCATENATE(sizing_w24_vcenter_appliance_size,sizing_w24_vcenter_storage_size),table_vcenter_disk_gb,2,FALSE),0), IF(sizing_w25_chosen="Included",VLOOKUP(CONCATENATE(sizing_w25_vcenter_appliance_size,sizing_w25_vcenter_storage_size),table_vcenter_disk_gb,2,FALSE),0), IF(sizing_w26_chosen="Included",VLOOKUP(CONCATENATE(sizing_w26_vcenter_appliance_size,sizing_w26_vcenter_storage_size),table_vcenter_disk_gb,2,FALSE),0), IF(sizing_w27_chosen="Included",VLOOKUP(CONCATENATE(sizing_w27_vcenter_appliance_size,sizing_w27_vcenter_storage_size),table_vcenter_disk_gb,2,FALSE),0), IF(sizing_w28_chosen="Included",VLOOKUP(CONCATENATE(sizing_w28_vcenter_appliance_size,sizing_w28_vcenter_storage_size),table_vcenter_disk_gb,2,FALSE),0), IF(sizing_w29_chosen="Included",VLOOKUP(CONCATENATE(sizing_w29_vcenter_appliance_size,sizing_w29_vcenter_storage_size),table_vcenter_disk_gb,2,FALSE),0), IF(sizing_w30_chosen="Included",VLOOKUP(CONCATENATE(sizing_w30_vcenter_appliance_size,sizing_w30_vcenter_storage_size),table_vcenter_disk_gb,2,FALSE),0), IF(sizing_w31_chosen="Included",VLOOKUP(CONCATENATE(sizing_w31_vcenter_appliance_size,sizing_w31_vcenter_storage_size),table_vcenter_disk_gb,2,FALSE),0), IF(sizing_w32_chosen="Included",VLOOKUP(CONCATENATE(sizing_w32_vcenter_appliance_size,sizing_w32_vcenter_storage_size),table_vcenter_disk_gb,2,FALSE),0), IF(sizing_w33_chosen="Included",VLOOKUP(CONCATENATE(sizing_w33_vcenter_appliance_size,sizing_w33_vcenter_storage_size),table_vcenter_disk_gb,2,FALSE),0), IF(sizing_w34_chosen="Included",VLOOKUP(CONCATENATE(sizing_w34_vcenter_appliance_size,sizing_w34_vcenter_storage_size),table_vcenter_disk_gb,2,FALSE),0), IF(sizing_w35_chosen="Included",VLOOKUP(CONCATENATE(sizing_w35_vcenter_appliance_size,sizing_w35_vcenter_storage_size),table_vcenter_disk_gb,2,FALSE),0), ) -> 0 | O18: Redundancy based on FTT1 | R18: =ROUNDUP(IF(sizing_storage_type="vSAN-ESA",R17*1.5,R17*2),0) -> 10778
